Workbook
Name Datenschnitt_L_P_E: #N/A
Name Datenschnitt_ST: #N/A
Name Datenschnitt_Team: #N/A
Name Einzelfilter_Gegner: OFFSET(Einzel!$D$10,0,0,COUNTA(Einzel!$D$10:$D$39),1)
Name Einzelfilter_Gesamt: OFFSET(Einzel!$E$10,0,0,COUNTA(Einzel!$E$10:$E$39),1)
Name Einzelfilter_Räumer: OFFSET(Einzel!$G$10,0,0,COUNTA(Einzel!$G$10:$G$39),1)
Name Einzelfilter_Schnitt: OFFSET(Einzel!$H$10,0,0,COUNTA(Einzel!$H$10:$H$39),1)
Name Einzelfilter_Volle: OFFSET(Einzel!$F$10,0,0,COUNTA(Einzel!$F$10:$F$39),1)

Sheet Kalender
A1: KW | B1: Datum | C1: Spiele | H1: KW
A2: =WEEKNUM(B2) -> 34 | B2: 45892 | C2: {=IF(COUNTIF(Chronologie[Datum],B2)=0,"","(") &TRANSPOSE(_xlfn._xlws.FILTER(Chronologie[ID],Chronologie[Datum]=B2,"")) &IF(COUNTIF(Chronologie[Datum],B2)=0,"",") ") &TRANSPOSE(_xlfn._xlws.FILTER(Chronologie[Gegner],Chronologie[Datum]=B2,"")) &IF(COUNTIF(Chronologie[Datum],B2)=0,""," [") &TRANSPOSE(_xlfn._xlws.FILTER(Chronologie[H/A],Chronologie[Datum]=B2,"")) &IF(COUNTIF(Chronologie[Datum],B2)=0,"","]") &CHAR(10) &TRANSPOSE(_xlfn._xlws.FILTER(Chronologie[Startzeit],Chronologie[Datum]=B2,""))} -> (U19-L-1) SV Fortschritt Pirna [A] 13:00 Uhr | H2: =A2 -> 34
B3: 45893 | C3: {=IF(COUNTIF(Chronologie[Datum],B3)=0,"","(") &TRANSPOSE(_xlfn._xlws.FILTER(Chronologie[ID],Chronologie[Datum]=B3,"")) &IF(COUNTIF(Chronologie[Datum],B3)=0,"",") ") &TRANSPOSE(_xlfn._xlws.FILTER(Chronologie[Gegner],Chronologie[Datum]=B3,"")) &IF(COUNTIF(Chronologie[Datum],B3)=0,""," [") &TRANSPOSE(_xlfn._xlws.FILTER(Chronologie[H/A],Chronologie[Datum]=B3,"")) &IF(COUNTIF(Chronologie[Datum],B3)=0,"","]") &CHAR(10) &TRANSPOSE(_xlfn._xlws.FILTER(Chronologie[Startzeit],Chronologie[Datum]=B3,""))}
A4: =WEEKNUM(B4) -> 35 | B4: =B2+7 -> 45899 | C4: {=IF(COUNTIF(Chronologie[Datum],B4)=0,"","(") &TRANSPOSE(_xlfn._xlws.FILTER(Chronologie[ID],Chronologie[Datum]=B4,"")) &IF(COUNTIF(Chronologie[Datum],B4)=0,"",") ") &TRANSPOSE(_xlfn._xlws.FILTER(Chronologie[Gegner],Chronologie[Datum]=B4,"")) &IF(COUNTIF(Chronologie[Datum],B4)=0,""," [") &TRANSPOSE(_xlfn._xlws.FILTER(Chronologie[H/A],Chronologie[Datum]=B4,"")) &IF(COUNTIF(Chronologie[Datum],B4)=0,"","]") &CHAR(10) &TRANSPOSE(_xlfn._xlws.FILTER(Chronologie[Startzeit],Chronologie[Datum]=B4,""))} -> (U19-L-2) MSV Bautzen 04 [A] 13:00 Uhr | H4: =A4 -> 35
B5: =B3+7 -> 45900 | C5: {=IF(COUNTIF(Chronologie[Datum],B5)=0,"","(") &TRANSPOSE(_xlfn._xlws.FILTER(Chronologie[ID],Chronologie[Datum]=B5,"")) &IF(COUNTIF(Chronologie[Datum],B5)=0,"",") ") &TRANSPOSE(_xlfn._xlws.FILTER(Chronologie[Gegner],Chronologie[Datum]=B5,"")) &IF(COUNTIF(Chronologie[Datum],B5)=0,""," [") &TRANSPOSE(_xlfn._xlws.FILTER(Chronologie[H/A],Chronologie[Datum]=B5,"")) &IF(COUNTIF(Chronologie[Datum],B5)=0,"","]") &CHAR(10) &TRANSPOSE(_xlfn._xlws.FILTER(Chronologie[Startzeit],Chronologie[Datum]=B5,""))}
A6: =WEEKNUM(B6) -> 36 | B6: =B4+7 -> 45906 | C6: {=IF(COUNTIF(Chronologie[Datum],B6)=0,"","(") &TRANSPOSE(_xlfn._xlws.FILTER(Chronologie[ID],Chronologie[Datum]=B6,"")) &IF(COUNTIF(Chronologie[Datum],B6)=0,"",") ") &TRANSPOSE(_xlfn._xlws.FILTER(Chronologie[Gegner],Chronologie[Datum]=B6,"")) &IF(COUNTIF(Chronologie[Datum],B6)=0,""," [") &TRANSPOSE(_xlfn._xlws.FILTER(Chronologie[H/A],Chronologie[Datum]=B6,"")) &IF(COUNTIF(Chronologie[Datum],B6)=0,"","]") &CHAR(10) &TRANSPOSE(_xlfn._xlws.FILTER(Chronologie[Startzeit],Chronologie[Datum]=B6,""))} | H6: =A6 -> 36
B7: =B5+7 -> 45907 | C7: {=IF(COUNTIF(Chronologie[Datum],B7)=0,"","(") &TRANSPOSE(_xlfn._xlws.FILTER(Chronologie[ID],Chronologie[Datum]=B7,"")) &IF(COUNTIF(Chronologie[Datum],B7)=0,"",") ") &TRANSPOSE(_xlfn._xlws.FILTER(Chronologie[Gegner],Chronologie[Datum]=B7,"")) &IF(COUNTIF(Chronologie[Datum],B7)=0,""," [") &TRANSPOSE(_xlfn._xlws.FILTER(Chronologie[H/A],Chronologie[Datum]=B7,"")) &IF(COUNTIF(Chronologie[Datum],B7)=0,"","]") &CHAR(10) &TRANSPOSE(_xlfn._xlws.FILTER(Chronologie[Startzeit],Chronologie[Datum]=B7,""))}
A8: =WEEKNUM(B8) -> 37 | B8: =B6+7 -> 45913 | C8: {=IF(COUNTIF(Chronologie[Datum],B8)=0,"","(") &TRANSPOSE(_xlfn._xlws.FILTER(Chronologie[ID],Chronologie[Datum]=B8,"")) &IF(COUNTIF(Chronologie[Datum],B8)=0,"",") ") &TRANSPOSE(_xlfn._xlws.FILTER(Chronologie[Gegner],Chronologie[Datum]=B8,"")) &IF(COUNTIF(Chronologie[Datum],B8)=0,""," [") &TRANSPOSE(_xlfn._xlws.FILTER(Chronologie[H/A],Chronologie[Datum]=B8,"")) &IF(COUNTIF(Chronologie[Datum],B8)=0,"","]") &CHAR(10) &TRANSPOSE(_xlfn._xlws.FILTER(Chronologie[Startzeit],Chronologie[Datum]=B8,""))} -> (E-L-1) TSV 90 Zwickau II [H] 13:00 Uhr | H8: =A8 -> 37
B9: =B7+7 -> 45914 | C9: {=IF(COUNTIF(Chronologie[Datum],B9)=0,"","(") &TRANSPOSE(_xlfn._xlws.FILTER(Chronologie[ID],Chronologie[Datum]=B9,"")) &IF(COUNTIF(Chronologie[Datum],B9)=0,"",") ") &TRANSPOSE(_xlfn._xlws.FILTER(Chronologie[Gegner],Chronologie[Datum]=B9,"")) &IF(COUNTIF(Chronologie[Datum],B9)=0,""," [") &TRANSPOSE(_xlfn._xlws.FILTER(Chronologie[H/A],Chronologie[Datum]=B9,"")) &IF(COUNTIF(Chronologie[Datum],B9)=0,"","]") &CHAR(10) &TRANSPOSE(_xlfn._xlws.FILTER(Chronologie[Startzeit],Chronologie[Datum]=B9,""))} -> (Z-L-1) ESV Zschorlau [A] 09:00 Uhr | D9: (U14-L-1) Hirschfelder SV [H] 09:00 Uhr
A10: =WEEKNUM(B10) -> 38 | B10: =B8+7 -> 45920 | C10: {=IF(COUNTIF(Chronologie[Datum],B10)=0,"","(") &TRANSPOSE(_xlfn._xlws.FILTER(Chronologie[ID],Chronologie[Datum]=B10,"")) &IF(COUNTIF(Chronologie[Datum],B10)=0,"",") ") &TRANSPOSE(_xlfn._xlws.FILTER(Chronologie[Gegner],Chronologie[Datum]=B10,"")) &IF(COUNTIF(Chronologie[Datum],B10)=0,""," [") &TRANSPOSE(_xlfn._xlws.FILTER(Chronologie[H/A],Chronologie[Datum]=B10,"")) &IF(COUNTIF(Chronologie[Datum],B10)=0,"","]") &CHAR(10) &TRANSPOSE(_xlfn._xlws.FILTER(Chronologie[Startzeit],Chronologie[Datum]=B10,""))} -> (E-L-2) SpG Großschirma/Brand-Erbisdorf [A] 13:00 Uhr | D10: (U19-L-3) Hirschfelder SV [H] 13:00 Uhr | H10: =A10 -> 38
B11: =B9+7 -> 45921 | C11: {=IF(COUNTIF(Chronologie[Datum],B11)=0,"","(") &TRANSPOSE(_xlfn._xlws.FILTER(Chronologie[ID],Chronologie[Datum]=B11,"")) &IF(COUNTIF(Chronologie[Datum],B11)=0,"",") ") &TRANSPOSE(_xlfn._xlws.FILTER(Chronologie[Gegner],Chronologie[Datum]=B11,"")) &IF(COUNTIF(Chronologie[Datum],B11)=0,""," [") &TRANSPOSE(_xlfn._xlws.FILTER(Chronologie[H/A],Chronologie[Datum]=B11,"")) &IF(COUNTIF(Chronologie[Datum],B11)=0,"","]") &CHAR(10) &TRANSPOSE(_xlfn._xlws.FILTER(Chronologie[Startzeit],Chronologie[Datum]=B11,""))} -> (F-L-1) Dresdner SV II [A] 09:15 Uhr | D11: (U14-L-2) SV Siltronic Freiberg [A] 12:20 Uhr
A12: =WEEKNUM(B12) -> 39 | B12: =B10+7 -> 45927 | C12: {=IF(COUNTIF(Chronologie[Datum],B12)=0,"","(") &TRANSPOSE(_xlfn._xlws.FILTER(Chronologie[ID],Chronologie[Datum]=B12,"")) &IF(COUNTIF(Chronologie[Datum],B12)=0,"",") ") &TRANSPOSE(_xlfn._xlws.FILTER(Chronologie[Gegner],Chronologie[Datum]=B12,"")) &IF(COUNTIF(Chronologie[Datum],B12)=0,""," [") &TRANSPOSE(_xlfn._xlws.FILTER(Chronologie[H/A],Chronologie[Datum]=B12,"")) &IF(COUNTIF(Chronologie[Datum],B12)=0,"","]") &CHAR(10) &TRANSPOSE(_xlfn._xlws.FILTER(Chronologie[Startzeit],Chronologie[Datum]=B12,""))} -> (E-L-3) SG Grün-Weiß Mehltheuer II [H] 14:00 Uhr | D12: (U14-L-3) TKV Flöha/Plaue [A] 09:00 Uhr | H12: =A12 -> 39
B13: =B11+7 -> 45928 | C13: {=IF(COUNTIF(Chronologie[Datum],B13)=0,"","(") &TRANSPOSE(_xlfn._xlws.FILTER(Chronologie[ID],Chronologie[Datum]=B13,"")) &IF(COUNTIF(Chronologie[Datum],B13)=0,"",") ") &TRANSPOSE(_xlfn._xlws.FILTER(Chronologie[Gegner],Chronologie[Datum]=B13,"")) &IF(COUNTIF(Chronologie[Datum],B13)=0,""," [") &TRANSPOSE(_xlfn._xlws.FILTER(Chronologie[H/A],Chronologie[Datum]=B13,"")) &IF(COUNTIF(Chronologie[Datum],B13)=0,"","]") &CHAR(10) &TRANSPOSE(_xlfn._xlws.FILTER(Chronologie[Startzeit],Chronologie[Datum]=B13,""))} -> (F-L-2) Thonberger SC 1931 [H] 09:00 Uhr
A14: =WEEKNUM(B14) -> 40 | B14: =B12+7 -> 45934 | C14: {=IF(COUNTIF(Chronologie[Datum],B14)=0,"","(") &TRANSPOSE(_xlfn._xlws.FILTER(Chronologie[ID],Chronologie[Datum]=B14,"")) &IF(COUNTIF(Chronologie[Datum],B14)=0,"",") ") &TRANSPOSE(_xlfn._xlws.FILTER(Chronologie[Gegner],Chronologie[Datum]=B14,"")) &IF(COUNTIF(Chronologie[Datum],B14)=0,""," [") &TRANSPOSE(_xlfn._xlws.FILTER(Chronologie[H/A],Chronologie[Datum]=B14,"")) &IF(COUNTIF(Chronologie[Datum],B14)=0,"","]") &CHAR(10) &TRANSPOSE(_xlfn._xlws.FILTER(Chronologie[Startzeit],Chronologie[Datum]=B14,""))} | H14: =A14 -> 40
B15: =B13+7 -> 45935 | C15: {=IF(COUNTIF(Chronologie[Datum],B15)=0,"","(") &TRANSPOSE(_xlfn._xlws.FILTER(Chronologie[ID],Chronologie[Datum]=B15,"")) &IF(COUNTIF(Chronologie[Datum],B15)=0,"",") ") &TRANSPOSE(_xlfn._xlws.FILTER(Chronologie[Gegner],Chronologie[Datum]=B15,"")) &IF(COUNTIF(Chronologie[Datum],B15)=0,""," [") &TRANSPOSE(_xlfn._xlws.FILTER(Chronologie[H/A],Chronologie[Datum]=B15,"")) &IF(COUNTIF(Chronologie[Datum],B15)=0,"","]") &CHAR(10) &TRANSPOSE(_xlfn._xlws.FILTER(Chronologie[Startzeit],Chronologie[Datum]=B15,""))}
A16: =WEEKNUM(B16) -> 41 | B16: =B14+7 -> 45941 | C16: {=IF(COUNTIF(Chronologie[Datum],B16)=0,"","(") &TRANSPOSE(_xlfn._xlws.FILTER(Chronologie[ID],Chronologie[Datum]=B16,"")) &IF(COUNTIF(Chronologie[Datum],B16)=0,"",") ") &TRANSPOSE(_xlfn._xlws.FILTER(Chronologie[Gegner],Chronologie[Datum]=B16,"")) &IF(COUNTIF(Chronologie[Datum],B16)=0,""," [") &TRANSPOSE(_xlfn._xlws.FILTER(Chronologie[H/A],Chronologie[Datum]=B16,"")) &IF(COUNTIF(Chronologie[Datum],B16)=0,"","]") &CHAR(10) &TRANSPOSE(_xlfn._xlws.FILTER(Chronologie[Startzeit],Chronologie[Datum]=B16,""))} | H16: =A16 -> 41
B17: =B15+7 -> 45942 | C17: {=IF(COUNTIF(Chronologie[Datum],B17)=0,"","(") &TRANSPOSE(_xlfn._xlws.FILTER(Chronologie[ID],Chronologie[Datum]=B17,"")) &IF(COUNTIF(Chronologie[Datum],B17)=0,"",") ") &TRANSPOSE(_xlfn._xlws.FILTER(Chronologie[Gegner],Chronologie[Datum]=B17,"")) &IF(COUNTIF(Chronologie[Datum],B17)=0,""," [") &TRANSPOSE(_xlfn._xlws.FILTER(Chronologie[H/A],Chronologie[Datum]=B17,"")) &IF(COUNTIF(Chronologie[Datum],B17)=0,"","]") &CHAR(10) &TRANSPOSE(_xlfn._xlws.FILTER(Chronologie[Startzeit],Chronologie[Datum]=B17,""))} -> (Z-L-2) SG Motor Thurm [H] 09:00 Uhr
A18: =WEEKNUM(B18) -> 42 | B18: =B16+7 -> 45948 | C18: {=IF(COUNTIF(Chronologie[Datum],B18)=0,"","(") &TRANSPOSE(_xlfn._xlws.FILTER(Chronologie[ID],Chronologie[Datum]=B18,"")) &IF(COUNTIF(Chronologie[Datum],B18)=0,"",") ") &TRANSPOSE(_xlfn._xlws.FILTER(Chronologie[Gegner],Chronologie[Datum]=B18,"")) &IF(COUNTIF(Chronologie[Datum],B18)=0,""," [") &TRANSPOSE(_xlfn._xlws.FILTER(Chronologie[H/A],Chronologie[Datum]=B18,"")) &IF(COUNTIF(Chronologie[Datum],B18)=0,"","]") &CHAR(10) &TRANSPOSE(_xlfn._xlws.FILTER(Chronologie[Startzeit],Chronologie[Datum]=B18,""))} -> (E-L-4) VfB Lengenfeld [H] 13:00 Uhr | H18: =A18 -> 42
B19: =B17+7 -> 45949 | C19: {=IF(COUNTIF(Chronologie[Datum],B19)=0,"","(") &TRANSPOSE(_xlfn._xlws.FILTER(Chronologie[ID],Chronologie[Datum]=B19,"")) &IF(COUNTIF(Chronologie[Datum],B19)=0,"",") ") &TRANSPOSE(_xlfn._xlws.FILTER(Chronologie[Gegner],Chronologie[Datum]=B19,"")) &IF(COUNTIF(Chronologie[Datum],B19)=0,""," [") &TRANSPOSE(_xlfn._xlws.FILTER(Chronologie[H/A],Chronologie[Datum]=B19,"")) &IF(COUNTIF(Chronologie[Datum],B19)=0,"","]") &CHAR(10) &TRANSPOSE(_xlfn._xlws.FILTER(Chronologie[Startzeit],Chronologie[Datum]=B19,""))} -> (Z-L-3) SKV 9-Pins Stollberg III [A] 09:00 Uhr | D19: (D-L-2) TSV 1848 Flöha [H] 09:00 Uhr
A20: =WEEKNUM(B20) -> 43 | B20: =B18+7 -> 45955 | C20: {=IF(COUNTIF(Chronologie[Datum],B20)=0,"","(") &TRANSPOSE(_xlfn._xlws.FILTER(Chronologie[ID],Chronologie[Datum]=B20,"")) &IF(COUNTIF(Chronologie[Datum],B20)=0,"",") ") &TRANSPOSE(_xlfn._xlws.FILTER(Chronologie[Gegner],Chronologie[Datum]=B20,"")) &IF(COUNTIF(Chronologie[Datum],B20)=0,""," [") &TRANSPOSE(_xlfn._xlws.FILTER(Chronologie[H/A],Chronologie[Datum]=B20,"")) &IF(COUNTIF(Chronologie[Datum],B20)=0,"","]") &CHAR(10) &TRANSPOSE(_xlfn._xlws.FILTER(Chronologie[Startzeit],Chronologie[Datum]=B20,""))} -> (E-L-5) SV Schönberg [A] 13:00 Uhr | H20: =A20 -> 43
B21: =B19+7 -> 45956 | C21: {=IF(COUNTIF(Chronologie[Datum],B21)=0,"","(") &TRANSPOSE(_xlfn._xlws.FILTER(Chronologie[ID],Chronologie[Datum]=B21,"")) &IF(COUNTIF(Chronologie[Datum],B21)=0,"",") ") &TRANSPOSE(_xlfn._xlws.FILTER(Chronologie[Gegner],Chronologie[Datum]=B21,"")) &IF(COUNTIF(Chronologie[Datum],B21)=0,""," [") &TRANSPOSE(_xlfn._xlws.FILTER(Chronologie[H/A],Chronologie[Datum]=B21,"")) &IF(COUNTIF(Chronologie[Datum],B21)=0,"","]") &CHAR(10) &TRANSPOSE(_xlfn._xlws.FILTER(Chronologie[Startzeit],Chronologie[Datum]=B21,""))} -> (F-L-3) KSV Dresden-Leuben [A] 09:00 Uhr | D21: (Z-L-4) KC "Gut Holz" Drebach [H] 09:00 Uhr
A22: =WEEKNUM(B22) -> 44 | B22: =B20+7 -> 45962 | C22: {=IF(COUNTIF(Chronologie[Datum],B22)=0,"","(") &TRANSPOSE(_xlfn._xlws.FILTER(Chronologie[ID],Chronologie[Datum]=B22,"")) &IF(COUNTIF(Chronologie[Datum],B22)=0,"",") ") &TRANSPOSE(_xlfn._xlws.FILTER(Chronologie[Gegner],Chronologie[Datum]=B22,"")) &IF(COUNTIF(Chronologie[Datum],B22)=0,""," [") &TRANSPOSE(_xlfn._xlws.FILTER(Chronologie[H/A],Chronologie[Datum]=B22,"")) &IF(COUNTIF(Chronologie[Datum],B22)=0,"","]") &CHAR(10) &TRANSPOSE(_xlfn._xlws.FILTER(Chronologie[Startzeit],Chronologie[Datum]=B22,""))} -> (U19-L-5) SKV 9-Pins Stollberg [A] 13:00 Uhr | D22: (D-L-3) SV Grün-Weiß Niederwiesa [A] 11:00 Uhr | E22: (E-DKBC-Pokal-2) TuS Gerolsheim [H] 13:00 Uhr | H22: =A22 -> 44
B23: =B21+7 -> 45963 | C23: {=IF(COUNTIF(Chronologie[Datum],B23)=0,"","(") &TRANSPOSE(_xlfn._xlws.FILTER(Chronologie[ID],Chronologie[Datum]=B23,"")) &IF(COUNTIF(Chronologie[Datum],B23)=0,"",") ") &TRANSPOSE(_xlfn._xlws.FILTER(Chronologie[Gegner],Chronologie[Datum]=B23,"")) &IF(COUNTIF(Chronologie[Datum],B23)=0,""," [") &TRANSPOSE(_xlfn._xlws.FILTER(Chronologie[H/A],Chronologie[Datum]=B23,"")) &IF(COUNTIF(Chronologie[Datum],B23)=0,"","]") &CHAR(10) &TRANSPOSE(_xlfn._xlws.FILTER(Chronologie[Startzeit],Chronologie[Datum]=B23,""))}
A24: =WEEKNUM(B24) -> 45 | B24: =B22+7 -> 45969 | C24: {=IF(COUNTIF(Chronologie[Datum],B24)=0,"","(") &TRANSPOSE(_xlfn._xlws.FILTER(Chronologie[ID],Chronologie[Datum]=B24,"")) &IF(COUNTIF(Chronologie[Datum],B24)=0,"",") ") &TRANSPOSE(_xlfn._xlws.FILTER(Chronologie[Gegner],Chronologie[Datum]=B24,"")) &IF(COUNTIF(Chronologie[Datum],B24)=0,""," [") &TRANSPOSE(_xlfn._xlws.FILTER(Chronologie[H/A],Chronologie[Datum]=B24,"")) &IF(COUNTIF(Chronologie[Datum],B24)=0,"","]") &CHAR(10) &TRANSPOSE(_xlfn._xlws.FILTER(Chronologie[Startzeit],Chronologie[Datum]=B24,""))} -> (E-L-6) KSV Blau-Gelb Taucha II [H] 13:00 Uhr | D24: (U14-L-4) SV Krummenhennersdorf [A] 12:20 Uhr | H24: =A24 -> 45
B25: =B23+7 -> 45970 | C25: {=IF(COUNTIF(Chronologie[Datum],B25)=0,"","(") &TRANSPOSE(_xlfn._xlws.FILTER(Chronologie[ID],Chronologie[Datum]=B25,"")) &IF(COUNTIF(Chronologie[Datum],B25)=0,"",") ") &TRANSPOSE(_xlfn._xlws.FILTER(Chronologie[Gegner],Chronologie[Datum]=B25,"")) &IF(COUNTIF(Chronologie[Datum],B25)=0,""," [") &TRANSPOSE(_xlfn._xlws.FILTER(Chronologie[H/A],Chronologie[Datum]=B25,"")) &IF(COUNTIF(Chronologie[Datum],B25)=0,"","]") &CHAR(10) &TRANSPOSE(_xlfn._xlws.FILTER(Chronologie[Startzeit],Chronologie[Datum]=B25,""))} -> (F-L-4) KSV 66 Steinitz [H] 09:00 Uhr | D25: (Z-L-5) TSV Geyer [A] 09:00 Uhr | E25: (U19-RLT-1) Hirschfelder SV [H]
A26: =WEEKNUM(B26) -> 46 | B26: =B24+7 -> 45976 | C26: {=IF(COUNTIF(Chronologie[Datum],B26)=0,"","(") &TRANSPOSE(_xlfn._xlws.FILTER(Chronologie[ID],Chronologie[Datum]=B26,"")) &IF(COUNTIF(Chronologie[Datum],B26)=0,"",") ") &TRANSPOSE(_xlfn._xlws.FILTER(Chronologie[Gegner],Chronologie[Datum]=B26,"")) &IF(COUNTIF(Chronologie[Datum],B26)=0,""," [") &TRANSPOSE(_xlfn._xlws.FILTER(Chronologie[H/A],Chronologie[Datum]=B26,"")) &IF(COUNTIF(Chronologie[Datum],B26)=0,"","]") &CHAR(10) &TRANSPOSE(_xlfn._xlws.FILTER(Chronologie[Startzeit],Chronologie[Datum]=B26,""))} -> (E-L-7) SG Hohentanne [H] 13:00 Uhr | D26: (D-L-4) SV Krummenhennersdorf [A] 11:00 Uhr | H26: =A26 -> 46
B27: =B25+7 -> 45977 | C27: {=IF(COUNTIF(Chronologie[Datum],B27)=0,"","(") &TRANSPOSE(_xlfn._xlws.FILTER(Chronologie[ID],Chronologie[Datum]=B27,"")) &IF(COUNTIF(Chronologie[Datum],B27)=0,"",") ") &TRANSPOSE(_xlfn._xlws.FILTER(Chronologie[Gegner],Chronologie[Datum]=B27,"")) &IF(COUNTIF(Chronologie[Datum],B27)=0,""," [") &TRANSPOSE(_xlfn._xlws.FILTER(Chronologie[H/A],Chronologie[Datum]=B27,"")) &IF(COUNTIF(Chronologie[Datum],B27)=0,"","]") &CHAR(10) &TRANSPOSE(_xlfn._xlws.FILTER(Chronologie[Startzeit],Chronologie[Datum]=B27,""))} -> (F-L-5) KSC Stahl Rietschen [A] 11:00 Uhr | D27: (Z-L-6) KSV Grün-Weiß Leubsdorf [H] 11:00 Uhr
A28: =WEEKNUM(B28) -> 47 | B28: =B26+7 -> 45983 | C28: {=IF(COUNTIF(Chronologie[Datum],B28)=0,"","(") &TRANSPOSE(_xlfn._xlws.FILTER(Chronologie[ID],Chronologie[Datum]=B28,"")) &IF(COUNTIF(Chronologie[Datum],B28)=0,"",") ") &TRANSPOSE(_xlfn._xlws.FILTER(Chronologie[Gegner],Chronologie[Datum]=B28,"")) &IF(COUNTIF(Chronologie[Datum],B28)=0,""," [") &TRANSPOSE(_xlfn._xlws.FILTER(Chronologie[H/A],Chronologie[Datum]=B28,"")) &IF(COUNTIF(Chronologie[Datum],B28)=0,"","]") &CHAR(10) &TRANSPOSE(_xlfn._xlws.FILTER(Chronologie[Startzeit],Chronologie[Datum]=B28,""))} -> (U19-L-6) SKV 9-Pins Stollberg [A] 13:00 Uhr | D28: (U14-BEL-1) VfB Lengenfeld [A] | E28: (E-P-1) SV Dölzig [A] | H28: =A28 -> 47
B29: =B27+7 -> 45984 | C29: {=IF(COUNTIF(Chronologie[Datum],B29)=0,"","(") &TRANSPOSE(_xlfn._xlws.FILTER(Chronologie[ID],Chronologie[Datum]=B29,"")) &IF(COUNTIF(Chronologie[Datum],B29)=0,"",") ") &TRANSPOSE(_xlfn._xlws.FILTER(Chronologie[Gegner],Chronologie[Datum]=B29,"")) &IF(COUNTIF(Chronologie[Datum],B29)=0,""," [") &TRANSPOSE(_xlfn._xlws.FILTER(Chronologie[H/A],Chronologie[Datum]=B29,"")) &IF(COUNTIF(Chronologie[Datum],B29)=0,"","]") &CHAR(10) &TRANSPOSE(_xlfn._xlws.FILTER(Chronologie[Startzeit],Chronologie[Datum]=B29,""))}
A30: =WEEKNUM(B30) -> 48 | B30: =B28+7 -> 45990 | C30: {=IF(COUNTIF(Chronologie[Datum],B30)=0,"","(") &TRANSPOSE(_xlfn._xlws.FILTER(Chronologie[ID],Chronologie[Datum]=B30,"")) &IF(COUNTIF(Chronologie[Datum],B30)=0,"",") ") &TRANSPOSE(_xlfn._xlws.FILTER(Chronologie[Gegner],Chronologie[Datum]=B30,"")) &IF(COUNTIF(Chronologie[Datum],B30)=0,""," [") &TRANSPOSE(_xlfn._xlws.FILTER(Chronologie[H/A],Chronologie[Datum]=B30,"")) &IF(COUNTIF(Chronologie[Datum],B30)=0,"","]") &CHAR(10) &TRANSPOSE(_xlfn._xlws.FILTER(Chronologie[Startzeit],Chronologie[Datum]=B30,""))} -> (E-L-8) SKV 9-Pins Stollberg II [H] 13:00 Uhr
B31: =B29+7 -> 45991 | C31: {=IF(COUNTIF(Chronologie[Datum],B31)=0,"","(") &TRANSPOSE(_xlfn._xlws.FILTER(Chronologie[ID],Chronologie[Datum]=B31,"")) &IF(COUNTIF(Chronologie[Datum],B31)=0,"",") ") &TRANSPOSE(_xlfn._xlws.FILTER(Chronologie[Gegner],Chronologie[Datum]=B31,"")) &IF(COUNTIF(Chronologie[Datum],B31)=0,""," [") &TRANSPOSE(_xlfn._xlws.FILTER(Chronologie[H/A],Chronologie[Datum]=B31,"")) &IF(COUNTIF(Chronologie[Datum],B31)=0,"","]") &CHAR(10) &TRANSPOSE(_xlfn._xlws.FILTER(Chronologie[Startzeit],Chronologie[Datum]=B31,""))} -> (F-L-6) ISG Hagenwerder [A] 09:15 Uhr | D31: (D-L-5) BKC 52 [H] 09:00 Uhr | E31: (U14-L-5) SV Rotation Weißenborn [A] 10:40 Uhr | F31: (U19-RLT-2) TSV Fortschritt Mittweida [A]
A32: =WEEKNUM(B32) -> 49 | B32: =B30+7 -> 45997 | C32: {=IF(COUNTIF(Chronologie[Datum],B32)=0,"","(") &TRANSPOSE(_xlfn._xlws.FILTER(Chronologie[ID],Chronologie[Datum]=B32,"")) &IF(COUNTIF(Chronologie[Datum],B32)=0,"",") ") &TRANSPOSE(_xlfn._xlws.FILTER(Chronologie[Gegner],Chronologie[Datum]=B32,"")) &IF(COUNTIF(Chronologie[Datum],B32)=0,""," [") &TRANSPOSE(_xlfn._xlws.FILTER(Chronologie[H/A],Chronologie[Datum]=B32,"")) &IF(COUNTIF(Chronologie[Datum],B32)=0,"","]") &CHAR(10) &TRANSPOSE(_xlfn._xlws.FILTER(Chronologie[Startzeit],Chronologie[Datum]=B32,""))} -> (U19-L-7) Hirschfelder SV [H] 13:00 Uhr | D32: (E-DKBC-Pokal-3) Lok Köthen [A] 13:30 Uhr
B33: =B31+7 -> 45998 | C33: {=IF(COUNTIF(Chronologie[Datum],B33)=0,"","(") &TRANSPOSE(_xlfn._xlws.FILTER(Chronologie[ID],Chronologie[Datum]=B33,"")) &IF(COUNTIF(Chronologie[Datum],B33)=0,"",") ") &TRANSPOSE(_xlfn._xlws.FILTER(Chronologie[Gegner],Chronologie[Datum]=B33,"")) &IF(COUNTIF(Chronologie[Datum],B33)=0,""," [") &TRANSPOSE(_xlfn._xlws.FILTER(Chronologie[H/A],Chronologie[Datum]=B33,"")) &IF(COUNTIF(Chronologie[Datum],B33)=0,"","]") &CHAR(10) &TRANSPOSE(_xlfn._xlws.FILTER(Chronologie[Startzeit],Chronologie[Datum]=B33,""))} -> (Z-L-7) KSV Hainichen 92 [A] 09:00 Uhr
A34: =WEEKNUM(B34) -> 50 | B34: =B32+7 -> 46004 | C34: {=IF(COUNTIF(Chronologie[Datum],B34)=0,"","(") &TRANSPOSE(_xlfn._xlws.FILTER(Chronologie[ID],Chronologie[Datum]=B34,"")) &IF(COUNTIF(Chronologie[Datum],B34)=0,"",") ") &TRANSPOSE(_xlfn._xlws.FILTER(Chronologie[Gegner],Chronologie[Datum]=B34,"")) &IF(COUNTIF(Chronologie[Datum],B34)=0,""," [") &TRANSPOSE(_xlfn._xlws.FILTER(Chronologie[H/A],Chronologie[Datum]=B34,"")) &IF(COUNTIF(Chronologie[Datum],B34)=0,"","]") &CHAR(10) &TRANSPOSE(_xlfn._xlws.FILTER(Chronologie[Startzeit],Chronologie[Datum]=B34,""))} -> (E-L-9) SV Rot-Weiß Treuen [A] 13:00 Uhr
B35: =B33+7 -> 46005 | C35: {=IF(COUNTIF(Chronologie[Datum],B35)=0,"","(") &TRANSPOSE(_xlfn._xlws.FILTER(Chronologie[ID],Chronologie[Datum]=B35,"")) &IF(COUNTIF(Chronologie[Datum],B35)=0,"",") ") &TRANSPOSE(_xlfn._xlws.FILTER(Chronologie[Gegner],Chronologie[Datum]=B35,"")) &IF(COUNTIF(Chronologie[Datum],B35)=0,""," [") &TRANSPOSE(_xlfn._xlws.FILTER(Chronologie[H/A],Chronologie[Datum]=B35,"")) &IF(COUNTIF(Chronologie[Datum],B35)=0,"","]") &CHAR(10) &TRANSPOSE(_xlfn._xlws.FILTER(Chronologie[Startzeit],Chronologie[Datum]=B35,""))} -> (Z-L-8) ESV Zschorlau [H] 09:00 Uhr
A36: =WEEKNUM(B36) -> 51 | B36: =B34+7 -> 46011 | C36: {=IF(COUNTIF(Chronologie[Datum],B36)=0,"","(") &TRANSPOSE(_xlfn._xlws.FILTER(Chronologie[ID],Chronologie[Datum]=B36,"")) &IF(COUNTIF(Chronologie[Datum],B36)=0,"",") ") &TRANSPOSE(_xlfn._xlws.FILTER(Chronologie[Gegner],Chronologie[Datum]=B36,"")) &IF(COUNTIF(Chronologie[Datum],B36)=0,""," [") &TRANSPOSE(_xlfn._xlws.FILTER(Chronologie[H/A],Chronologie[Datum]=B36,"")) &IF(COUNTIF(Chronologie[Datum],B36)=0,"","]") &CHAR(10) &TRANSPOSE(_xlfn._xlws.FILTER(Chronologie[Startzeit],Chronologie[Datum]=B36,""))} | H36: =A36 -> 51
B37: =B35+7 -> 46012 | C37: {=IF(COUNTIF(Chronologie[Datum],B37)=0,"","(") &TRANSPOSE(_xlfn._xlws.FILTER(Chronologie[ID],Chronologie[Datum]=B37,"")) &IF(COUNTIF(Chronologie[Datum],B37)=0,"",") ") &TRANSPOSE(_xlfn._xlws.FILTER(Chronologie[Gegner],Chronologie[Datum]=B37,"")) &IF(COUNTIF(Chronologie[Datum],B37)=0,""," [") &TRANSPOSE(_xlfn._xlws.FILTER(Chronologie[H/A],Chronologie[Datum]=B37,"")) &IF(COUNTIF(Chronologie[Datum],B37)=0,"","]") &CHAR(10) &TRANSPOSE(_xlfn._xlws.FILTER(Chronologie[Startzeit],Chronologie[Datum]=B37,""))}
A38: Winterpause + Weihnachten
A40: =WEEKNUM(B40) -> 2 | B40: 46032 | C40: {=IF(COUNTIF(Chronologie[Datum],B40)=0,"","(") &TRANSPOSE(_xlfn._xlws.FILTER(Chronologie[ID],Chronologie[Datum]=B40,"")) &IF(COUNTIF(Chronologie[Datum],B40)=0,"",") ") &TRANSPOSE(_xlfn._xlws.FILTER(Chronologie[Gegner],Chronologie[Datum]=B40,"")) &IF(COUNTIF(Chronologie[Datum],B40)=0,""," [") &TRANSPOSE(_xlfn._xlws.FILTER(Chronologie[H/A],Chronologie[Datum]=B40,"")) &IF(COUNTIF(Chronologie[Datum],B40)=0,"","]") &CHAR(10) &TRANSPOSE(_xlfn._xlws.FILTER(Chronologie[Startzeit],Chronologie[Datum]=B40,""))} -> (U19-L-8) MSV Bautzen 04 [A] 13:00 Uhr | D40: (U23-KEM-V) TuS 1875 Großschirma [A] | E40: (Ü60-KEM-V) KSV Grün-Weiß Leubsdorf [A] | F40: (Ü50-KEM-V) TuS 1875 Großschirma [A] | G40: (M-KEM-V) SV Linda [A] | H40: =A40 -> 2
B41: 46033 | C41: {=IF(COUNTIF(Chronologie[Datum],B41)=0,"","(") &TRANSPOSE(_xlfn._xlws.FILTER(Chronologie[ID],Chronologie[Datum]=B41,"")) &IF(COUNTIF(Chronologie[Datum],B41)=0,"",") ") &TRANSPOSE(_xlfn._xlws.FILTER(Chronologie[Gegner],Chronologie[Datum]=B41,"")) &IF(COUNTIF(Chronologie[Datum],B41)=0,""," [") &TRANSPOSE(_xlfn._xlws.FILTER(Chronologie[H/A],Chronologie[Datum]=B41,"")) &IF(COUNTIF(Chronologie[Datum],B41)=0,"","]") &CHAR(10) &TRANSPOSE(_xlfn._xlws.FILTER(Chronologie[Startzeit],Chronologie[Datum]=B41,""))}
...

Sheet Export
A1: Auswärts
A2: Name | B2: Team | C2: Spiele | D2: Volle | E2: Räumer | F2: Fehler | G2: GES | H2: SP | I2: MP | J2: S1 | K2: S2 | L2: S3 | M2: S4 | N2: SP 1 | O2: SP 2 | P2: SP 3 | Q2: SP 4 | R2: Trend (Saison) | S2: Trend (letzte 3 Spiele) | T2: STABW | U2: GEG GES | V2: Häufigste Position | W2: Anzahl häufigste Position | X2: Beste Position | Y2: % Beste Position | Z2: Rang | AA2: =IF(A1="Heim","Lieblingsbahn","")
A3: {=IF(A1="Gesamt",_xlfn._xlws.SORT(_xlfn.CHOOSECOLS(_xlfn._xlws.FILTER(AuswertungG[],AuswertungG[Spiele]>0,""),1,2,3,5,6,7,8,9,10,11,12,13,14,15,16,17,18,19,20,21,22,23,24,25,26,27),7,-1,FALSE),IF(A1="Heim",_xlfn._xlws.SORT(_xlfn.CHOOSECOLS(_xlfn._xlws.FILTER(AuswertungH[],AuswertungH[Spiele H]>0),1,2,3,5,6,7,8,9,10,11,12,13,14,15,16,17,18,19,20,21,22,23,24,25,26,27,28),7,-1,FALSE),IF(A1="Auswärts",_xlfn._xlws.SORT(_xlfn.CHOOSECOLS(_xlfn._xlws.FILTER(AuswertungA[],AuswertungA[Spiele A]>0),1,2,3,5,6,7,8,9,10,11,12,13,14,15,16,17,18,19,20,21,22,23,24,25,26,27),7,-1,FALSE),"")))} -> Philipp Paulmann | B3: E | C3: 5 | D3: 368 | E3: 198 | F3: 4.6 | G3: 566 | H3: 1.7 | I3: 0.4 | J3: 151 | K3: 142 | L3: 137 | M3: 134 | N3: 0.7 | O3: 0.6 | P3: 0.2 | Q3: 0.2 | R3: -0.92 | S3: -9.54 | T3: 47 | U3: 574 | V3: [6] | W3: 3 | X3: [5] | Y3: 0.5 | Z3: 2.8
A4: Maik Fuhrmann | B4: E | C4: 8 | D4: 370 | E4: 191 | F4: 3.4 | G4: 561 | H4: 3.42 | I4: 1 | J4: 141 | K4: 138 | L4: 141 | M4: 146 | N4: 0.92 | O4: 0.83 | P4: 0.83 | Q4: 0.83 | R4: 1.2 | S4: -8.78 | T4: 39 | U4: 520 | V4: [1][2] | W4: 2 | X4: [1][2][3][4] | Y4: 1 | Z4: 2
A5: Heiko Fuhrmann | B5: E | C5: 6 | D5: 368 | E5: 179 | F5: 6.3 | G5: 547 | H5: 2.17 | I5: 0.33 | J5: 147 | K5: 130 | L5: 137 | M5: 133 | N5: 0.83 | O5: 0.5 | P5: 0.33 | Q5: 0.5 | R5: 3.43 | S5: 5.02 | T5: 25 | U5: 552 | V5: [5] | W5: 3 | X5: [5] | Y5: 0.67 | Z5: 3.4
A6: Tim Beger | B6: Z | C6: 7 | D6: 368 | E6: 178 | F6: 7.6 | G6: 546 | H6: 1.9 | I6: 0.6 | J6: 142 | K6: 131 | L6: 130 | M6: 140 | N6: 0.8 | O6: 0.2 | P6: 0.4 | Q6: 0.5 | R6: -2.37 | S6: -19.86 | T6: 24 | U6: 543 | V6: [6] | W6: 2 | X6: [2][3][5] | Y6: 1 | Z6: 2.6
A7: Stefan Teuber | B7: E | C7: 5 | D7: 368 | E7: 177 | F7: 6.4 | G7: 545 | H7: 2.1 | I7: 0.4 | J7: 136 | K7: 138 | L7: 133 | M7: 138 | N7: 0.5 | O7: 0.8 | P7: 0.4 | Q7: 0.4 | R7: 2.45 | S7: 3.98 | T7: 21 | U7: 551 | V7: [2][4] | W7: 2 | X7: [1] | Y7: 1 | Z7: 3
A8: Patrick Frenzel | B8: D | C8: 1 | D8: 351 | E8: 191 | F8: 12 | G8: 542 | H8: 2 | I8: 0 | J8: 140 | K8: 126 | L8: 130 | M8: 146 | N8: 1 | O8: 0 | P8: 0 | Q8: 1 | U8: 550 | V8: [4] | W8: 1 | X8: [4] | Y8: 0 | Z8: 1
A9: Stefan Ulbricht | B9: Z | C9: 4 | D9: 354 | E9: 188 | F9: 6.3 | G9: 542 | H9: 2.75 | I9: 0.75 | J9: 130 | K9: 134 | L9: 139 | M9: 138 | N9: 0.5 | O9: 0.75 | P9: 0.75 | Q9: 0.75 | R9: -5.34 | S9: -13.13 | T9: 51 | U9: 490 | V9: [4] | W9: 3 | X9: [4] | Y9: 1 | Z9: 3.8
A10: Emma Hettmann | B10: U19 | C10: 8 | D10: 367 | E10: 172 | F10: 4.8 | G10: 540 | J10: 142 | K10: 134 | L10: 134 | M10: 131 | R10: -0.32 | S10: -0.03 | T10: 20 | Z10: 1.2
A11: Uwe Zippack | B11: Z | C11: 5 | D11: 357 | E11: 181 | F11: 4.4 | G11: 538 | H11: 2.2 | I11: 0.6 | J11: 139 | K11: 130 | L11: 129 | M11: 140 | N11: 0.6 | O11: 0.2 | P11: 0.6 | Q11: 0.8 | R11: -3.24 | S11: -6.07 | T11: 23 | U11: 539 | V11: [2] | W11: 2 | X11: [4][6] | Y11: 1 | Z11: 3
A12: Erik Krutak | B12: Z | C12: 7 | D12: 353 | E12: 181 | F12: 5.9 | G12: 534 | H12: 1.2 | I12: 0 | J12: 135 | K12: 127 | L12: 130 | M12: 142 | N12: 0.2 | O12: 0.2 | P12: 0 | Q12: 0.8 | R12: -0.86 | S12: -0.07 | T12: 21 | U12: 556 | V12: [5] | W12: 3 | X12: [5][6] | Y12: 0 | Z12: 4
A13: Mario Hägemann | B13: Z | C13: 5 | D13: 356 | E13: 176 | F13: 5.2 | G13: 532 | H13: 2.5 | I13: 0.8 | J13: 136 | K13: 132 | L13: 130 | M13: 133 | N13: 0.6 | O13: 0.6 | P13: 0.5 | Q13: 0.8 | R13: 0.37 | S13: -4.21 | T13: 20 | U13: 519 | V13: [1][3] | W13: 2 | X13: [1][3] | Y13: 1 | Z13: 3.2
A14: Olaf Kurtze | B14: Z | C14: 4 | D14: 367 | E14: 165 | F14: 8.8 | G14: 531 | H14: 1.75 | I14: 0.25 | J14: 133 | K14: 132 | L14: 128 | M14: 139 | N14: 0.5 | O14: 0.5 | P14: 0.25 | Q14: 0.5 | R14: -2.14 | S14: -7.66 | T14: 31 | U14: 543 | V14: [1] | W14: 3 | X14: [1] | Y14: 0.33 | Z14: 3.5
A15: Peter Paulmann | B15: D | C15: 4 | D15: 350 | E15: 176 | F15: 7 | G15: 527 | H15: 2.25 | I15: 0.5 | J15: 140 | K15: 127 | L15: 126 | M15: 138 | N15: 1 | O15: 0.5 | P15: 0.5 | Q15: 0.25 | R15: 3.51 | S15: -4.29 | T15: 23 | U15: 511 | V15: [5][6] | W15: 1 | X15: [6] | Y15: 1 | Z15: 2.5
A16: Tim Becker | B16: E | C16: 3 | D16: 365 | E16: 162 | F16: 6.3 | G16: 527 | H16: 1.83 | I16: 0.33 | J16: 122 | K16: 138 | L16: 134 | M16: 133 | N16: 0.17 | O16: 0.67 | P16: 0.33 | Q16: 0.67 | R16: 2.53 | S16: 2.53 | T16: 23 | U16: 546 | V16: [3] | W16: 3 | X16: [3] | Y16: 0.33 | Z16: 4
A17: Madlen Baumgarten | B17: F | C17: 5 | D17: 353 | E17: 173 | F17: 7.4 | G17: 526 | H17: 2 | I17: 0.6 | J17: 131 | K17: 125 | L17: 141 | M17: 130 | N17: 0.6 | O17: 0.4 | P17: 0.6 | Q17: 0.4 | R17: 0.06 | S17: -4.29 | T17: 21 | U17: 528 | V17: [5] | W17: 3 | X17: [2] | Y17: 1 | Z17: 2
A18: Sylke Schmidt | B18: F | C18: 4 | D18: 367 | E18: 158 | F18: 11 | G18: 524 | H18: 2.25 | I18: 0.75 | J18: 131 | K18: 138 | L18: 128 | M18: 127 | N18: 0.75 | O18: 0.5 | P18: 0.5 | Q18: 0.5 | R18: 2.68 | S18: 1.04 | T18: 24 | U18: 504 | V18: [5][6] | W18: 2 | X18: [6] | Y18: 1 | Z18: 3
A19: Patrick Hohmann | B19: E | C19: 6 | D19: 356 | E19: 164 | F19: 7.7 | G19: 520 | H19: 2 | I19: 0.38 | J19: 128 | K19: 137 | L19: 127 | M19: 130 | N19: 0.75 | O19: 0.5 | P19: 0.25 | Q19: 0.5 | R19: -0.05 | S19: -0.62 | T19: 21 | U19: 538 | V19: [1][3][4][6] | W19: 1 | X19: [4] | Y19: 1 | Z19: 4
A20: Florian Jäger | B20: D | C20: 1 | D20: 325 | E20: 186 | F20: 4 | G20: 511 | H20: 3 | I20: 1 | J20: 137 | K20: 134 | L20: 129 | M20: 111 | N20: 1 | O20: 1 | P20: 1 | Q20: 0 | U20: 481 | V20: [6] | W20: 1 | X20: [6] | Y20: 1 | Z20: 3
A21: Heike Scholz | B21: F | C21: 6 | D21: 348 | E21: 163 | F21: 8 | G21: 511 | H21: 1.75 | I21: 0.75 | J21: 131 | K21: 125 | L21: 123 | M21: 137 | N21: 0.5 | O21: 0.25 | P21: 0.25 | Q21: 0.75 | R21: 0.38 | S21: 9.57 | T21: 15 | U21: 527 | V21: [4] | W21: 3 | X21: [3] | Y21: 1 | Z21: 2.8
A22: Katrin Fiedler | B22: F | C22: 3 | D22: 358 | E22: 152 | F22: 11 | G22: 510 | H22: 1.67 | I22: 0.33 | J22: 129 | K22: 132 | L22: 125 | M22: 124 | N22: 0.33 | O22: 0.33 | P22: 0.33 | Q22: 0.67 | R22: 3.3 | S22: 3.3 | T22: 29 | U22: 535 | V22: [6] | W22: 2 | X22: [6] | Y22: 0.5 | Z22: 3.3
A23: Andreas Rippin | B23: E | C23: 4 | D23: 350 | E23: 159 | F23: 11.5 | G23: 509 | H23: 0.75 | I23: 0 | J23: 121 | K23: 130 | L23: 133 | M23: 126 | N23: 0.25 | O23: 0.25 | P23: 0.25 | Q23: 0 | R23: 6.17 | S23: 6.39 | T23: 41 | U23: 572 | V23: [2] | W23: 2 | X23: [1][2][5] | Y23: 0 | Z23: 5.3
A24: Jens Starke | B24: D | C24: 3 | D24: 346 | E24: 162 | F24: 7.7 | G24: 507 | H24: 1.5 | I24: 0.33 | J24: 120 | K24: 123 | L24: 130 | M24: 134 | N24: 0.33 | O24: 0.33 | P24: 0.5 | Q24: 0.33 | R24: -2.11 | S24: -2.11 | T24: 13 | U24: 520 | V24: [1][3][4] | W24: 1 | X24: [4] | Y24: 1 | Z24: 3.3
A25: Anna Müller | B25: U19 | C25: 8 | D25: 349 | E25: 157 | F25: 9.6 | G25: 506 | J25: 127 | K25: 130 | L25: 119 | M25: 130 | R25: -0.54 | S25: -0.61 | T25: 19 | Z25: 2.3
A26: Cora Keller | B26: U19 | C26: 10 | D26: 348 | E26: 154 | F26: 11.6 | G26: 502 | H26: 2 | I26: 0.67 | J26: 130 | K26: 127 | L26: 122 | M26: 123 | N26: 0.33 | O26: 0.67 | P26: 0.67 | Q26: 0.33 | R26: -0.12 | S26: 24.5 | T26: 33 | U26: 482 | V26: [1][2][3] | W26: 1 | X26: [2][3] | Y26: 1 | Z26: 2.6
A27: Ulli Baumgarten | B27: D | C27: 3 | D27: 361 | E27: 139 | F27: 10 | G27: 499 | H27: 2 | I27: 0.67 | J27: 122 | K27: 126 | L27: 128 | M27: 123 | N27: 0.33 | O27: 0.67 | P27: 0.67 | Q27: 0.33 | R27: 2.58 | S27: 2.58 | T27: 12 | U27: 499 | V27: [2][3][5] | W27: 1 | X27: [2][3] | Y27: 1 | Z27: 4.7
A28: Peter Weißling | B28: D | C28: 1 | D28: 342 | E28: 145 | F28: 8 | G28: 487 | H28: 2 | I28: 1 | J28: 113 | K28: 138 | L28: 130 | M28: 106 | N28: 0 | O28: 1 | P28: 1 | Q28: 0 | U28: 473 | V28: [3] | W28: 1 | X28: [3] | Y28: 1 | Z28: 5
A29: Jörg Nötzel | B29: D | C29: 3 | D29: 354 | E29: 130 | F29: 14.3 | G29: 484 | H29: 2 | I29: 0.5 | J29: 127 | K29: 124 | L29: 128 | M29: 128 | N29: 0.5 | O29: 0 | P29: 1 | Q29: 0.5 | R29: -1.47 | S29: -1.47 | T29: 30 | U29: 517 | V29: [2][3] | W29: 1 | X29: [2] | Y29: 1 | Z29: 5
A30: Lea Meinert | B30: F | C30: 5 | D30: 342 | E30: 142 | F30: 9 | G30: 483 | H30: 0.67 | I30: 0 | J30: 124 | K30: 118 | L30: 122 | M30: 119 | N30: 0 | O30: 0 | P30: 0.33 | Q30: 0.33 | R30: 1.15 | S30: 6.14 | T30: 30 | U30: 507 | V30: [1] | W30: 2 | X30: [1][2] | Y30: 0 | Z30: 5.3
A31: Marcel Giese | B31: D | C31: 2 | D31: 338 | E31: 143 | F31: 16 | G31: 480 | H31: 2.5 | I31: 1 | J31: 112 | K31: 120 | L31: 118 | M31: 131 | N31: 0.5 | O31: 1 | P31: 0 | Q31: 1 | R31: 22 | S31: 22 | T31: 11 | U31: 490 | V31: [1] | W31: 1 | X31: [1] | Y31: 1 | Z31: 5
A32: Pia Wätzig | B32: U19 | C32: 9 | D32: 331 | E32: 136 | F32: 15.2 | G32: 467 | H32: 0.5 | I32: 0 | J32: 119 | K32: 119 | L32: 112 | M32: 117 | N32: 0 | O32: 0 | P32: 0 | Q32: 0.5 | R32: 1.22 | S32: 24.5 | T32: 30 | U32: 539 | V32: [1][3] | W32: 1 | X32: [1][3] | Y32: 0 | Z32: 4
A33: Katrin Keller | B33: F | C33: 7 | D33: 328 | E33: 138 | F33: 11.6 | G33: 466 | H33: 1.7 | I33: 0.4 | J33: 120 | K33: 128 | L33: 119 | M33: 100 | N33: 0.4 | O33: 0.8 | P33: 0.4 | Q33: 0.1 | R33: 1.8 | S33: 27.14 | T33: 43 | U33: 509 | V33: [2][3] | W33: 2 | X33: [2][3] | Y33: 0.5 | Z33: 4.4
A34: Emelie Schiffel | B34: U14 | C34: 8 | D34: 302 | E34: 109 | F34: 23.1 | G34: 411 | J34: 104 | K34: 111 | L34: 95 | M34: 99 | R34: -0.83 | S34: -2.42 | T34: 42 | Z34: 2
A35: Sophia Stirl | B35: U14 | C35: 6 | D35: 296 | E35: 95 | F35: 24.8 | G35: 391 | J35: 96 | K35: 101 | L35: 95 | M35: 99 | R35: 1.61 | S35: -2.76 | T35: 33 | Z35: 2
A36: Bruno Bergelt | B36: U14 | C36: 4 | D36: 285 | E36: 99 | F36: 22 | G36: 383 | J36: 99 | K36: 97 | L36: 90 | M36: 98 | R36: 1.7 | S36: 3.62 | T36: 13 | Z36: 2
A37: Lisa Marutschke | B37: U14 | C37: 7 | D37: 274 | E37: 89 | F37: 28.4 | G37: 363 | J37: 82 | K37: 91 | L37: 92 | M37: 99 | R37: -0.44 | S37: 0.62 | T37: 25 | Z37: 3
A38: Ben Böhmer | B38: U14 | C38: 4 | D38: 249 | E38: 80 | F38: 34.8 | G38: 329 | J38: 85 | K38: 93 | L38: 68 | M38: 86 | R38: 1.34 | S38: 0.21 | T38: 21 | Z38: 3.5

Sheet Übersicht
A1: Teams | E1: Chronologie | Y1: Kegelbahnverzeichnis
A2: Nummer | B2: Name | C2: Team | E2: SA-NR | F2: ID | G2: Datum | H2: Team | I2: L/P/E | J2: ST | K2: Gegner | L2: Ort | M2: H/A | N2: SANR | O2: Gespielt | P2: Eingetragen? | Q2: KW | R2: Kurzform | S2: Bahnen | T2: Startzeit | U2: Start | V2: Endzeit | X2: Gegner | Y2: Anschrift | Z2: PLZ | AA2: Ort | AB2: Kurzform | AC2: Bahnen
A3: =ROW(A3)-2 -> 1 | B3: Anastasia Landau | C3: F | E3: =ROW(E3)-2 -> 1 | F3: =Chronologie[[#This Row],[Team]]&"-"&Chronologie[[#This Row],[L/P/E]]&"-"&Chronologie[[#This Row],[ST]] -> E-L-1 | G3: 45913 | H3: E | I3: L | J3: 1 | K3: TSV 90 Zwickau II | L3: =IF(Chronologie[[#This Row],[H/A]]="A",VLOOKUP(Chronologie[[#This Row],[Gegner]],Orte[],4,FALSE),IF(Chronologie[[#This Row],[H/A]]="H","Hirschfeld",Chronologie[[#This Row],[Gegner]])) -> Hirschfeld | M3: H | N3: =Chronologie[[#This Row],[SA-NR]] -> 1 | O3: =IF(Chronologie[[#This Row],[Datum]]="","",IF(TODAY()>=Chronologie[[#This Row],[Datum]],1,0)) -> 1 | P3: =IF(COUNTIFS(Eingabe[ID],Chronologie[[#This Row],[ID]],Eingabe[GES],">0")>=1,1,0) -> 1 | Q3: =IF(YEAR(Chronologie[[#This Row],[Datum]])=2025,WEEKNUM(Chronologie[[#This Row],[Datum]],2)-34,IF(YEAR(Chronologie[[#This Row],[Datum]])=2026,WEEKNUM(Chronologie[[#This Row],[Datum]],2)+18,"")) -> 3 | R3: =IF(Chronologie[[#This Row],[Gegner]]="","",VLOOKUP(Chronologie[[#This Row],[Gegner]],Orte[],5,FALSE)) -> Zwickau | S3: =IF(Chronologie[[#This Row],[Gegner]]="","",IF(Chronologie[[#This Row],[H/A]]="H",4,VLOOKUP(Chronologie[[#This Row],[Gegner]],Orte[],6,FALSE))) -> 4 | T3: 13:00 Uhr | U3: =IFERROR(TIMEVALUE(LEFT(Chronologie[[#This Row],[Startzeit]],5)),"") -> 0.54166667 | V3: =IFERROR(TIMEVALUE(LEFT(Chronologie[[#This Row],[Startzeit]],5))+TIME(12/Chronologie[[#This Row],[Bahnen]],0,0),"") -> 0.66666667 | X3: BKC 52 | Y3: Jahnstraße 11, 09618 Brand-Erbisdorf | Z3: 9618 | AA3: =IF(Orte[[#This Row],[Anschrift]]="",Orte[[#This Row],[Kurzform]],RIGHT(Orte[[#This Row],[Anschrift]],LEN(Orte[[#This Row],[Anschrift]])-FIND("#",SUBSTITUTE(Orte[[#This Row],[Anschrift]]," ","#",LEN(Orte[[#This Row],[Anschrift]])-LEN(SUBSTITUTE(Orte[[#This Row],[Anschrift]]," ",)))))) -> Brand-Erbisdorf | AB3: BKC | AC3: 4
A4: =ROW(A4)-2 -> 2 | B4: Andreas Ehrlich | C4: D | E4: =ROW(E4)-2 -> 2 | F4: =Chronologie[[#This Row],[Team]]&"-"&Chronologie[[#This Row],[L/P/E]]&"-"&Chronologie[[#This Row],[ST]] -> E-L-2 | G4: 45920 | H4: E | I4: L | J4: 2 | K4: SpG Großschirma/Brand-Erbisdorf | L4: =IF(Chronologie[[#This Row],[H/A]]="A",VLOOKUP(Chronologie[[#This Row],[Gegner]],Orte[],4,FALSE),IF(Chronologie[[#This Row],[H/A]]="H","Hirschfeld",Chronologie[[#This Row],[Gegner]])) -> Brand-Erbisdorf | M4: A | N4: =Chronologie[[#This Row],[SA-NR]] -> 2 | O4: =IF(Chronologie[[#This Row],[Datum]]="","",IF(TODAY()>=Chronologie[[#This Row],[Datum]],1,0)) -> 1 | P4: =IF(COUNTIFS(Eingabe[ID],Chronologie[[#This Row],[ID]],Eingabe[GES],">0")>=1,1,0) -> 1 | Q4: =IF(YEAR(Chronologie[[#This Row],[Datum]])=2025,WEEKNUM(Chronologie[[#This Row],[Datum]],2)-34,IF(YEAR(Chronologie[[#This Row],[Datum]])=2026,WEEKNUM(Chronologie[[#This Row],[Datum]],2)+18,"")) -> 4 | R4: =IF(Chronologie[[#This Row],[Gegner]]="","",VLOOKUP(Chronologie[[#This Row],[Gegner]],Orte[],5,FALSE)) -> Großschirma | S4: =IF(Chronologie[[#This Row],[Gegner]]="","",IF(Chronologie[[#This Row],[H/A]]="H",4,VLOOKUP(Chronologie[[#This Row],[Gegner]],Orte[],6,FALSE))) -> 4 | T4: 13:00 Uhr | U4: =IFERROR(TIMEVALUE(LEFT(Chronologie[[#This Row],[Startzeit]],5)),"") -> 0.54166667 | V4: =IFERROR(TIMEVALUE(LEFT(Chronologie[[#This Row],[Startzeit]],5))+TIME(12/Chronologie[[#This Row],[Bahnen]],0,0),"") -> 0.66666667 | X4: BSC Motor Rochlitz | Y4: Am Regenbogen 23, 09306 Rochlitz | Z4: 9306 | AA4: =IF(Orte[[#This Row],[Anschrift]]="",Orte[[#This Row],[Kurzform]],RIGHT(Orte[[#This Row],[Anschrift]],LEN(Orte[[#This Row],[Anschrift]])-FIND("#",SUBSTITUTE(Orte[[#This Row],[Anschrift]]," ","#",LEN(Orte[[#This Row],[Anschrift]])-LEN(SUBSTITUTE(Orte[[#This Row],[Anschrift]]," ",)))))) -> Rochlitz | AB4: Rochlitz | AC4: 4
A5: =ROW(A5)-2 -> 3 | B5: Andreas Rippin | C5: E | E5: =ROW(E5)-2 -> 3 | F5: =Chronologie[[#This Row],[Team]]&"-"&Chronologie[[#This Row],[L/P/E]]&"-"&Chronologie[[#This Row],[ST]] -> E-L-3 | G5: 45927 | H5: E | I5: L | J5: 3 | K5: SG Grün-Weiß Mehltheuer II | L5: =IF(Chronologie[[#This Row],[H/A]]="A",VLOOKUP(Chronologie[[#This Row],[Gegner]],Orte[],4,FALSE),IF(Chronologie[[#This Row],[H/A]]="H","Hirschfeld",Chronologie[[#This Row],[Gegner]])) -> Hirschfeld | M5: H | N5: =Chronologie[[#This Row],[SA-NR]] -> 3 | O5: =IF(Chronologie[[#This Row],[Datum]]="","",IF(TODAY()>=Chronologie[[#This Row],[Datum]],1,0)) -> 1 | P5: =IF(COUNTIFS(Eingabe[ID],Chronologie[[#This Row],[ID]],Eingabe[GES],">0")>=1,1,0) -> 1 | Q5: =IF(YEAR(Chronologie[[#This Row],[Datum]])=2025,WEEKNUM(Chronologie[[#This Row],[Datum]],2)-34,IF(YEAR(Chronologie[[#This Row],[Datum]])=2026,WEEKNUM(Chronologie[[#This Row],[Datum]],2)+18,"")) -> 5 | R5: =IF(Chronologie[[#This Row],[Gegner]]="","",VLOOKUP(Chronologie[[#This Row],[Gegner]],Orte[],5,FALSE)) -> Mehltheuer | S5: =IF(Chronologie[[#This Row],[Gegner]]="","",IF(Chronologie[[#This Row],[H/A]]="H",4,VLOOKUP(Chronologie[[#This Row],[Gegner]],Orte[],6,FALSE))) -> 4 | T5: 14:00 Uhr | U5: =IFERROR(TIMEVALUE(LEFT(Chronologie[[#This Row],[Startzeit]],5)),"") -> 0.58333333 | V5: =IFERROR(TIMEVALUE(LEFT(Chronologie[[#This Row],[Startzeit]],5))+TIME(12/Chronologie[[#This Row],[Bahnen]],0,0),"") -> 0.70833333 | X5: BSV Ehrenfriedersdorf | Y5: Wiesenstraße 18, 09427 Ehrenfriedersdorf | Z5: 9427 | AA5: =IF(Orte[[#This Row],[Anschrift]]="",Orte[[#This Row],[Kurzform]],RIGHT(Orte[[#This Row],[Anschrift]],LEN(Orte[[#This Row],[Anschrift]])-FIND("#",SUBSTITUTE(Orte[[#This Row],[Anschrift]]," ","#",LEN(Orte[[#This Row],[Anschrift]])-LEN(SUBSTITUTE(Orte[[#This Row],[Anschrift]]," ",)))))) -> Ehrenfriedersdorf | AB5: Ehrenfriedersdorf | AC5: 4
A6: =ROW(A6)-2 -> 4 | B6: Anna Müller | C6: U19 | E6: =ROW(E6)-2 -> 4 | F6: =Chronologie[[#This Row],[Team]]&"-"&Chronologie[[#This Row],[L/P/E]]&"-"&Chronologie[[#This Row],[ST]] -> E-L-4 | G6: 45948 | H6: E | I6: L | J6: 4 | K6: VfB Lengenfeld | L6: =IF(Chronologie[[#This Row],[H/A]]="A",VLOOKUP(Chronologie[[#This Row],[Gegner]],Orte[],4,FALSE),IF(Chronologie[[#This Row],[H/A]]="H","Hirschfeld",Chronologie[[#This Row],[Gegner]])) -> Hirschfeld | M6: H | N6: =Chronologie[[#This Row],[SA-NR]] -> 4 | O6: =IF(Chronologie[[#This Row],[Datum]]="","",IF(TODAY()>=Chronologie[[#This Row],[Datum]],1,0)) -> 1 | P6: =IF(COUNTIFS(Eingabe[ID],Chronologie[[#This Row],[ID]],Eingabe[GES],">0")>=1,1,0) -> 1 | Q6: =IF(YEAR(Chronologie[[#This Row],[Datum]])=2025,WEEKNUM(Chronologie[[#This Row],[Datum]],2)-34,IF(YEAR(Chronologie[[#This Row],[Datum]])=2026,WEEKNUM(Chronologie[[#This Row],[Datum]],2)+18,"")) -> 8 | R6: =IF(Chronologie[[#This Row],[Gegner]]="","",VLOOKUP(Chronologie[[#This Row],[Gegner]],Orte[],5,FALSE)) -> Lengenfeld | S6: =IF(Chronologie[[#This Row],[Gegner]]="","",IF(Chronologie[[#This Row],[H/A]]="H",4,VLOOKUP(Chronologie[[#This Row],[Gegner]],Orte[],6,FALSE))) -> 4 | T6: 13:00 Uhr | U6: =IFERROR(TIMEVALUE(LEFT(Chronologie[[#This Row],[Startzeit]],5)),"") -> 0.54166667 | V6: =IFERROR(TIMEVALUE(LEFT(Chronologie[[#This Row],[Startzeit]],5))+TIME(12/Chronologie[[#This Row],[Bahnen]],0,0),"") -> 0.66666667 | X6: Chemnitzer SV Siegmar 48 | Y6: Jagdschänkenstraße 35, 09117 Chemnitz | Z6: 9117 | AA6: =IF(Orte[[#This Row],[Anschrift]]="",Orte[[#This Row],[Kurzform]],RIGHT(Orte[[#This Row],[Anschrift]],LEN(Orte[[#This Row],[Anschrift]])-FIND("#",SUBSTITUTE(Orte[[#This Row],[Anschrift]]," ","#",LEN(Orte[[#This Row],[Anschrift]])-LEN(SUBSTITUTE(Orte[[#This Row],[Anschrift]]," ",)))))) -> Chemnitz | AB6: Siegmar | AC6: 4
A7: =ROW(A7)-2 -> 5 | B7: Ben Becker | C7: D | E7: =ROW(E7)-2 -> 5 | F7: =Chronologie[[#This Row],[Team]]&"-"&Chronologie[[#This Row],[L/P/E]]&"-"&Chronologie[[#This Row],[ST]] -> E-L-5 | G7: 45955 | H7: E | I7: L | J7: 5 | K7: SV Schönberg | L7: =IF(Chronologie[[#This Row],[H/A]]="A",VLOOKUP(Chronologie[[#This Row],[Gegner]],Orte[],4,FALSE),IF(Chronologie[[#This Row],[H/A]]="H","Hirschfeld",Chronologie[[#This Row],[Gegner]])) -> Glauchau | M7: A | N7: =Chronologie[[#This Row],[SA-NR]] -> 5 | O7: =IF(Chronologie[[#This Row],[Datum]]="","",IF(TODAY()>=Chronologie[[#This Row],[Datum]],1,0)) -> 1 | P7: =IF(COUNTIFS(Eingabe[ID],Chronologie[[#This Row],[ID]],Eingabe[GES],">0")>=1,1,0) -> 1 | Q7: =IF(YEAR(Chronologie[[#This Row],[Datum]])=2025,WEEKNUM(Chronologie[[#This Row],[Datum]],2)-34,IF(YEAR(Chronologie[[#This Row],[Datum]])=2026,WEEKNUM(Chronologie[[#This Row],[Datum]],2)+18,"")) -> 9 | R7: =IF(Chronologie[[#This Row],[Gegner]]="","",VLOOKUP(Chronologie[[#This Row],[Gegner]],Orte[],5,FALSE)) -> Schönberg | S7: =IF(Chronologie[[#This Row],[Gegner]]="","",IF(Chronologie[[#This Row],[H/A]]="H",4,VLOOKUP(Chronologie[[#This Row],[Gegner]],Orte[],6,FALSE))) -> 4 | T7: 13:00 Uhr | U7: =IFERROR(TIMEVALUE(LEFT(Chronologie[[#This Row],[Startzeit]],5)),"") -> 0.54166667 | V7: =IFERROR(TIMEVALUE(LEFT(Chronologie[[#This Row],[Startzeit]],5))+TIME(12/Chronologie[[#This Row],[Bahnen]],0,0),"") -> 0.66666667 | X7: Dresdner SV II | Y7: Weißeritzstr. 4, 01067 Dresden | Z7: 1067 | AA7: =IF(Orte[[#This Row],[Anschrift]]="",Orte[[#This Row],[Kurzform]],RIGHT(Orte[[#This Row],[Anschrift]],LEN(Orte[[#This Row],[Anschrift]])-FIND("#",SUBSTITUTE(Orte[[#This Row],[Anschrift]]," ","#",LEN(Orte[[#This Row],[Anschrift]])-LEN(SUBSTITUTE(Orte[[#This Row],[Anschrift]]," ",)))))) -> Dresden | AB7: DD SV II | AC7: 4
A8: =ROW(A8)-2 -> 6 | B8: Ben Böhmer | C8: U14 | E8: =ROW(E8)-2 -> 6 | F8: =Chronologie[[#This Row],[Team]]&"-"&Chronologie[[#This Row],[L/P/E]]&"-"&Chronologie[[#This Row],[ST]] -> E-L-6 | G8: 45969 | H8: E | I8: L | J8: 6 | K8: KSV Blau-Gelb Taucha II | L8: =IF(Chronologie[[#This Row],[H/A]]="A",VLOOKUP(Chronologie[[#This Row],[Gegner]],Orte[],4,FALSE),IF(Chronologie[[#This Row],[H/A]]="H","Hirschfeld",Chronologie[[#This Row],[Gegner]])) -> Hirschfeld | M8: H | N8: =Chronologie[[#This Row],[SA-NR]] -> 6 | O8: =IF(Chronologie[[#This Row],[Datum]]="","",IF(TODAY()>=Chronologie[[#This Row],[Datum]],1,0)) -> 1 | P8: =IF(COUNTIFS(Eingabe[ID],Chronologie[[#This Row],[ID]],Eingabe[GES],">0")>=1,1,0) -> 1 | Q8: =IF(YEAR(Chronologie[[#This Row],[Datum]])=2025,WEEKNUM(Chronologie[[#This Row],[Datum]],2)-34,IF(YEAR(Chronologie[[#This Row],[Datum]])=2026,WEEKNUM(Chronologie[[#This Row],[Datum]],2)+18,"")) -> 11 | R8: =IF(Chronologie[[#This Row],[Gegner]]="","",VLOOKUP(Chronologie[[#This Row],[Gegner]],Orte[],5,FALSE)) -> Taucha | S8: =IF(Chronologie[[#This Row],[Gegner]]="","",IF(Chronologie[[#This Row],[H/A]]="H",4,VLOOKUP(Chronologie[[#This Row],[Gegner]],Orte[],6,FALSE))) -> 4 | T8: 13:00 Uhr | U8: =IFERROR(TIMEVALUE(LEFT(Chronologie[[#This Row],[Startzeit]],5)),"") -> 0.54166667 | V8: =IFERROR(TIMEVALUE(LEFT(Chronologie[[#This Row],[Startzeit]],5))+TIME(12/Chronologie[[#This Row],[Bahnen]],0,0),"") -> 0.66666667 | X8: ESV Zschorlau | Y8: Schulstraße 2, 08321 Zschorlau | Z8: 8321 | AA8: =IF(Orte[[#This Row],[Anschrift]]="",Orte[[#This Row],[Kurzform]],RIGHT(Orte[[#This Row],[Anschrift]],LEN(Orte[[#This Row],[Anschrift]])-FIND("#",SUBSTITUTE(Orte[[#This Row],[Anschrift]]," ","#",LEN(Orte[[#This Row],[Anschrift]])-LEN(SUBSTITUTE(Orte[[#This Row],[Anschrift]]," ",)))))) -> Zschorlau | AB8: Zschorlau | AC8: 4
A9: =ROW(A9)-2 -> 7 | B9: Bruno Bergelt | C9: U14 | E9: =ROW(E9)-2 -> 7 | F9: =Chronologie[[#This Row],[Team]]&"-"&Chronologie[[#This Row],[L/P/E]]&"-"&Chronologie[[#This Row],[ST]] -> E-L-7 | G9: 45976 | H9: E | I9: L | J9: 7 | K9: SG Hohentanne | L9: =IF(Chronologie[[#This Row],[H/A]]="A",VLOOKUP(Chronologie[[#This Row],[Gegner]],Orte[],4,FALSE),IF(Chronologie[[#This Row],[H/A]]="H","Hirschfeld",Chronologie[[#This Row],[Gegner]])) -> Hirschfeld | M9: H | N9: =Chronologie[[#This Row],[SA-NR]] -> 7 | O9: =IF(Chronologie[[#This Row],[Datum]]="","",IF(TODAY()>=Chronologie[[#This Row],[Datum]],1,0)) -> 1 | P9: =IF(COUNTIFS(Eingabe[ID],Chronologie[[#This Row],[ID]],Eingabe[GES],">0")>=1,1,0) -> 1 | Q9: =IF(YEAR(Chronologie[[#This Row],[Datum]])=2025,WEEKNUM(Chronologie[[#This Row],[Datum]],2)-34,IF(YEAR(Chronologie[[#This Row],[Datum]])=2026,WEEKNUM(Chronologie[[#This Row],[Datum]],2)+18,"")) -> 12 | R9: =IF(Chronologie[[#This Row],[Gegner]]="","",VLOOKUP(Chronologie[[#This Row],[Gegner]],Orte[],5,FALSE)) -> Hohentanne | S9: =IF(Chronologie[[#This Row],[Gegner]]="","",IF(Chronologie[[#This Row],[H/A]]="H",4,VLOOKUP(Chronologie[[#This Row],[Gegner]],Orte[],6,FALSE))) -> 4 | T9: 13:00 Uhr | U9: =IFERROR(TIMEVALUE(LEFT(Chronologie[[#This Row],[Startzeit]],5)),"") -> 0.54166667 | V9: =IFERROR(TIMEVALUE(LEFT(Chronologie[[#This Row],[Startzeit]],5))+TIME(12/Chronologie[[#This Row],[Bahnen]],0,0),"") -> 0.66666667 | X9: Hirschfeld | Y9: Reinsberger Straße 2, 09634 Hirschfeld | Z9: 9634 | AA9: =IF(Orte[[#This Row],[Anschrift]]="",Orte[[#This Row],[Kurzform]],RIGHT(Orte[[#This Row],[Anschrift]],LEN(Orte[[#This Row],[Anschrift]])-FIND("#",SUBSTITUTE(Orte[[#This Row],[Anschrift]]," ","#",LEN(Orte[[#This Row],[Anschrift]])-LEN(SUBSTITUTE(Orte[[#This Row],[Anschrift]]," ",)))))) -> Hirschfeld | AB9: Hirschfeld | AC9: 4
A10: =ROW(A10)-2 -> 8 | B10: Cora Keller | C10: U19 | E10: =ROW(E10)-2 -> 8 | F10: =Chronologie[[#This Row],[Team]]&"-"&Chronologie[[#This Row],[L/P/E]]&"-"&Chronologie[[#This Row],[ST]] -> E-L-8 | G10: 45990 | H10: E | I10: L | J10: 8 | K10: SKV 9-Pins Stollberg II | L10: =IF(Chronologie[[#This Row],[H/A]]="A",VLOOKUP(Chronologie[[#This Row],[Gegner]],Orte[],4,FALSE),IF(Chronologie[[#This Row],[H/A]]="H","Hirschfeld",Chronologie[[#This Row],[Gegner]])) -> Hirschfeld | M10: H | N10: =Chronologie[[#This Row],[SA-NR]] -> 8 | O10: =IF(Chronologie[[#This Row],[Datum]]="","",IF(TODAY()>=Chronologie[[#This Row],[Datum]],1,0)) -> 1 | P10: =IF(COUNTIFS(Eingabe[ID],Chronologie[[#This Row],[ID]],Eingabe[GES],">0")>=1,1,0) -> 1 | Q10: =IF(YEAR(Chronologie[[#This Row],[Datum]])=2025,WEEKNUM(Chronologie[[#This Row],[Datum]],2)-34,IF(YEAR(Chronologie[[#This Row],[Datum]])=2026,WEEKNUM(Chronologie[[#This Row],[Datum]],2)+18,"")) -> 14 | R10: =IF(Chronologie[[#This Row],[Gegner]]="","",VLOOKUP(Chronologie[[#This Row],[Gegner]],Orte[],5,FALSE)) -> Stollberg III | S10: =IF(Chronologie[[#This Row],[Gegner]]="","",IF(Chronologie[[#This Row],[H/A]]="H",4,VLOOKUP(Chronologie[[#This Row],[Gegner]],Orte[],6,FALSE))) -> 4 | T10: 13:00 Uhr | U10: =IFERROR(TIMEVALUE(LEFT(Chronologie[[#This Row],[Startzeit]],5)),"") -> 0.54166667 | V10: =IFERROR(TIMEVALUE(LEFT(Chronologie[[#This Row],[Startzeit]],5))+TIME(12/Chronologie[[#This Row],[Bahnen]],0,0),"") -> 0.66666667 | X10: Hirschfelder SV | Y10: Reinsberger Straße 2, 09634 Hirschfeld | Z10: 9634 | AA10: =IF(Orte[[#This Row],[Anschrift]]="",Orte[[#This Row],[Kurzform]],RIGHT(Orte[[#This Row],[Anschrift]],LEN(Orte[[#This Row],[Anschrift]])-FIND("#",SUBSTITUTE(Orte[[#This Row],[Anschrift]]," ","#",LEN(Orte[[#This Row],[Anschrift]])-LEN(SUBSTITUTE(Orte[[#This Row],[Anschrift]]," ",)))))) -> Hirschfeld | AB10: HSV | AC10: 4
A11: =ROW(A11)-2 -> 9 | B11: Dietmar Klose | C11: D | E11: =ROW(E11)-2 -> 9 | F11: =Chronologie[[#This Row],[Team]]&"-"&Chronologie[[#This Row],[L/P/E]]&"-"&Chronologie[[#This Row],[ST]] -> E-L-9 | G11: 46004 | H11: E | I11: L | J11: 9 | K11: SV Rot-Weiß Treuen | L11: =IF(Chronologie[[#This Row],[H/A]]="A",VLOOKUP(Chronologie[[#This Row],[Gegner]],Orte[],4,FALSE),IF(Chronologie[[#This Row],[H/A]]="H","Hirschfeld",Chronologie[[#This Row],[Gegner]])) -> Treuen | M11: A | N11: =Chronologie[[#This Row],[SA-NR]] -> 9 | O11: =IF(Chronologie[[#This Row],[Datum]]="","",IF(TODAY()>=Chronologie[[#This Row],[Datum]],1,0)) -> 1 | P11: =IF(COUNTIFS(Eingabe[ID],Chronologie[[#This Row],[ID]],Eingabe[GES],">0")>=1,1,0) -> 1 | Q11: =IF(YEAR(Chronologie[[#This Row],[Datum]])=2025,WEEKNUM(Chronologie[[#This Row],[Datum]],2)-34,IF(YEAR(Chronologie[[#This Row],[Datum]])=2026,WEEKNUM(Chronologie[[#This Row],[Datum]],2)+18,"")) -> 16 | R11: =IF(Chronologie[[#This Row],[Gegner]]="","",VLOOKUP(Chronologie[[#This Row],[Gegner]],Orte[],5,FALSE)) -> Treuen | S11: =IF(Chronologie[[#This Row],[Gegner]]="","",IF(Chronologie[[#This Row],[H/A]]="H",4,VLOOKUP(Chronologie[[#This Row],[Gegner]],Orte[],6,FALSE))) -> 4 | T11: 13:00 Uhr | U11: =IFERROR(TIMEVALUE(LEFT(Chronologie[[#This Row],[Startzeit]],5)),"") -> 0.54166667 | V11: =IFERROR(TIMEVALUE(LEFT(Chronologie[[#This Row],[Startzeit]],5))+TIME(12/Chronologie[[#This Row],[Bahnen]],0,0),"") -> 0.66666667 | X11: Hohnstädter SV | Y11: Seumeparkweg 1, 04668 Hohnstädt | Z11: 4668 | AA11: =IF(Orte[[#This Row],[Anschrift]]="",Orte[[#This Row],[Kurzform]],RIGHT(Orte[[#This Row],[Anschrift]],LEN(Orte[[#This Row],[Anschrift]])-FIND("#",SUBSTITUTE(Orte[[#This Row],[Anschrift]]," ","#",LEN(Orte[[#This Row],[Anschrift]])-LEN(SUBSTITUTE(Orte[[#This Row],[Anschrift]]," ",)))))) -> Hohnstädt | AB11: Hohnstädt | AC11: 4
A12: =ROW(A12)-2 -> 10 | B12: Emelie Schiffel | C12: U14 | E12: =ROW(E12)-2 -> 10 | F12: =Chronologie[[#This Row],[Team]]&"-"&Chronologie[[#This Row],[L/P/E]]&"-"&Chronologie[[#This Row],[ST]] -> E-L-10 | G12: 46039 | H12: E | I12: L | J12: 10 | K12: TSV 90 Zwickau II | L12: =IF(Chronologie[[#This Row],[H/A]]="A",VLOOKUP(Chronologie[[#This Row],[Gegner]],Orte[],4,FALSE),IF(Chronologie[[#This Row],[H/A]]="H","Hirschfeld",Chronologie[[#This Row],[Gegner]])) -> Zwickau | M12: A | N12: =Chronologie[[#This Row],[SA-NR]] -> 10 | O12: =IF(Chronologie[[#This Row],[Datum]]="","",IF(TODAY()>=Chronologie[[#This Row],[Datum]],1,0)) -> 1 | P12: =IF(COUNTIFS(Eingabe[ID],Chronologie[[#This Row],[ID]],Eingabe[GES],">0")>=1,1,0) -> 1 | Q12: =IF(YEAR(Chronologie[[#This Row],[Datum]])=2025,WEEKNUM(Chronologie[[#This Row],[Datum]],2)-34,IF(YEAR(Chronologie[[#This Row],[Datum]])=2026,WEEKNUM(Chronologie[[#This Row],[Datum]],2)+18,"")) -> 21 | R12: =IF(Chronologie[[#This Row],[Gegner]]="","",VLOOKUP(Chronologie[[#This Row],[Gegner]],Orte[],5,FALSE)) -> Zwickau | S12: =IF(Chronologie[[#This Row],[Gegner]]="","",IF(Chronologie[[#This Row],[H/A]]="H",4,VLOOKUP(Chronologie[[#This Row],[Gegner]],Orte[],6,FALSE))) -> 6 | T12: 13:30 Uhr | U12: =IFERROR(TIMEVALUE(LEFT(Chronologie[[#This Row],[Startzeit]],5)),"") -> 0.5625 | V12: =IFERROR(TIMEVALUE(LEFT(Chronologie[[#This Row],[Startzeit]],5))+TIME(12/Chronologie[[#This Row],[Bahnen]],0,0),"") -> 0.64583333 | X12: KC "Gut Holz" Drebach | Y12: Hopfgartener Str. 38 D, 09430 Drebach / OT Scharfenstein | Z12: 9430 | AA12: =IF(Orte[[#This Row],[Anschrift]]="",Orte[[#This Row],[Kurzform]],RIGHT(Orte[[#This Row],[Anschrift]],LEN(Orte[[#This Row],[Anschrift]])-FIND("#",SUBSTITUTE(Orte[[#This Row],[Anschrift]]," ","#",LEN(Orte[[#This Row],[Anschrift]])-LEN(SUBSTITUTE(Orte[[#This Row],[Anschrift]]," ",)))))) -> Scharfenstein | AB12: Drebach | AC12: 2
A13: =ROW(A13)-2 -> 11 | B13: Emma Hettmann | C13: U19 | E13: =ROW(E13)-2 -> 11 | F13: =Chronologie[[#This Row],[Team]]&"-"&Chronologie[[#This Row],[L/P/E]]&"-"&Chronologie[[#This Row],[ST]] -> E-L-11 | G13: 46046 | H13: E | I13: L | J13: 11 | K13: SpG Großschirma/Brand-Erbisdorf | L13: =IF(Chronologie[[#This Row],[H/A]]="A",VLOOKUP(Chronologie[[#This Row],[Gegner]],Orte[],4,FALSE),IF(Chronologie[[#This Row],[H/A]]="H","Hirschfeld",Chronologie[[#This Row],[Gegner]])) -> Hirschfeld | M13: H | N13: =Chronologie[[#This Row],[SA-NR]] -> 11 | O13: =IF(Chronologie[[#This Row],[Datum]]="","",IF(TODAY()>=Chronologie[[#This Row],[Datum]],1,0)) -> 1 | P13: =IF(COUNTIFS(Eingabe[ID],Chronologie[[#This Row],[ID]],Eingabe[GES],">0")>=1,1,0) -> 1 | Q13: =IF(YEAR(Chronologie[[#This Row],[Datum]])=2025,WEEKNUM(Chronologie[[#This Row],[Datum]],2)-34,IF(YEAR(Chronologie[[#This Row],[Datum]])=2026,WEEKNUM(Chronologie[[#This Row],[Datum]],2)+18,"")) -> 22 | R13: =IF(Chronologie[[#This Row],[Gegner]]="","",VLOOKUP(Chronologie[[#This Row],[Gegner]],Orte[],5,FALSE)) -> Großschirma | S13: =IF(Chronologie[[#This Row],[Gegner]]="","",IF(Chronologie[[#This Row],[H/A]]="H",4,VLOOKUP(Chronologie[[#This Row],[Gegner]],Orte[],6,FALSE))) -> 4 | T13: 13:00 Uhr | U13: =IFERROR(TIMEVALUE(LEFT(Chronologie[[#This Row],[Startzeit]],5)),"") -> 0.54166667 | V13: =IFERROR(TIMEVALUE(LEFT(Chronologie[[#This Row],[Startzeit]],5))+TIME(12/Chronologie[[#This Row],[Bahnen]],0,0),"") -> 0.66666667 | X13: KC 69 Marienberg | Y13: Katharinenstraße 20b, 09496 Marienberg | Z13: 9496 | AA13: =IF(Orte[[#This Row],[Anschrift]]="",Orte[[#This Row],[Kurzform]],RIGHT(Orte[[#This Row],[Anschrift]],LEN(Orte[[#This Row],[Anschrift]])-FIND("#",SUBSTITUTE(Orte[[#This Row],[Anschrift]]," ","#",LEN(Orte[[#This Row],[Anschrift]])-LEN(SUBSTITUTE(Orte[[#This Row],[Anschrift]]," ",)))))) -> Marienberg | AB13: Marienberg | AC13: 2
A14: =ROW(A14)-2 -> 12 | B14: Erik Krutak | C14: Z | E14: =ROW(E14)-2 -> 12 | F14: =Chronologie[[#This Row],[Team]]&"-"&Chronologie[[#This Row],[L/P/E]]&"-"&Chronologie[[#This Row],[ST]] -> E-L-12 | G14: 46060 | H14: E | I14: L | J14: 12 | K14: SG Grün-Weiß Mehltheuer II | L14: =IF(Chronologie[[#This Row],[H/A]]="A",VLOOKUP(Chronologie[[#This Row],[Gegner]],Orte[],4,FALSE),IF(Chronologie[[#This Row],[H/A]]="H","Hirschfeld",Chronologie[[#This Row],[Gegner]])) -> Mehltheuer | M14: A | N14: =Chronologie[[#This Row],[SA-NR]] -> 12 | O14: =IF(Chronologie[[#This Row],[Datum]]="","",IF(TODAY()>=Chronologie[[#This Row],[Datum]],1,0)) -> 0 | P14: =IF(COUNTIFS(Eingabe[ID],Chronologie[[#This Row],[ID]],Eingabe[GES],">0")>=1,1,0) -> 0 | Q14: =IF(YEAR(Chronologie[[#This Row],[Datum]])=2025,WEEKNUM(Chronologie[[#This Row],[Datum]],2)-34,IF(YEAR(Chronologie[[#This Row],[Datum]])=2026,WEEKNUM(Chronologie[[#This Row],[Datum]],2)+18,"")) -> 24 | R14: =IF(Chronologie[[#This Row],[Gegner]]="","",VLOOKUP(Chronologie[[#This Row],[Gegner]],Orte[],5,FALSE)) -> Mehltheuer | S14: =IF(Chronologie[[#This Row],[Gegner]]="","",IF(Chronologie[[#This Row],[H/A]]="H",4,VLOOKUP(Chronologie[[#This Row],[Gegner]],Orte[],6,FALSE))) -> 4 | T14: 13:00 Uhr | U14: =IFERROR(TIMEVALUE(LEFT(Chronologie[[#This Row],[Startzeit]],5)),"") -> 0.54166667 | V14: =IFERROR(TIMEVALUE(LEFT(Chronologie[[#This Row],[Startzeit]],5))+TIME(12/Chronologie[[#This Row],[Bahnen]],0,0),"") -> 0.66666667 | X14: Kirchberger KV 1845 | Y14: Marienthaler Str. 120, 08060 Zwickau | Z14: 8060 | AA14: =IF(Orte[[#This Row],[Anschrift]]="",Orte[[#This Row],[Kurzform]],RIGHT(Orte[[#This Row],[Anschrift]],LEN(Orte[[#This Row],[Anschrift]])-FIND("#",SUBSTITUTE(Orte[[#This Row],[Anschrift]]," ","#",LEN(Orte[[#This Row],[Anschrift]])-LEN(SUBSTITUTE(Orte[[#This Row],[Anschrift]]," ",)))))) -> Zwickau | AB14: Kirchberg | AC14: 4
... A26: =ROW(A26)-2 -> 24 | B26: Luca Landau | C26: D | E26: =ROW(E26)-2 -> 24 | F26: =Chronologie[[#This Row],[Team]]&"-"&Chronologie[[#This Row],[L/P/E]]&"-"&Chronologie[[#This Row],[ST]] -> F-L-6 | G26: 45991 | H26: F | I26: L | J26: 6 | K26: ISG Hagenwerder | L26: =IF(Chronologie[[#This Row],[H/A]]="A",VLOOKUP(Chronologie[[#This Row],[Gegner]],Orte[],4,FALSE),IF(Chronologie[[#This Row],[H/A]]="H","Hirschfeld",Chronologie[[#This Row],[Gegner]])) -> Hagenwerder | M26: A | N26: =Chronologie[[#This Row],[SA-NR]] -> 24 | O26: =IF(Chronologie[[#This Row],[Datum]]="","",IF(TODAY()>=Chronologie[[#This Row],[Datum]],1,0)) -> 1 | P26: =IF(COUNTIFS(Eingabe[ID],Chronologie[[#This Row],[ID]],Eingabe[GES],">0")>=1,1,0) -> 1 | Q26: =IF(YEAR(Chronologie[[#This Row],[Datum]])=2025,WEEKNUM(Chronologie[[#This Row],[Datum]],2)-34,IF(YEAR(Chronologie[[#This Row],[Datum]])=2026,WEEKNUM(Chronologie[[#This Row],[Datum]],2)+18,"")) -> 14 | R26: =IF(Chronologie[[#This Row],[Gegner]]="","",VLOOKUP(Chronologie[[#This Row],[Gegner]],Orte[],5,FALSE)) -> Hagenwerder | S26: =IF(Chronologie[[#This Row],[Gegner]]="","",IF(Chronologie[[#This Row],[H/A]]="H",4,VLOOKUP(Chronologie[[#This Row],[Gegner]],Orte[],6,FALSE))) -> 4 | T26: 09:15 Uhr | U26: =IFERROR(TIMEVALUE(LEFT(Chronologie[[#This Row],[Startzeit]],5)),"") -> 0.38541667 | V26: =IFERROR(TIMEVALUE(LEFT(Chronologie[[#This Row],[Startzeit]],5))+TIME(12/Chronologie[[#This Row],[Bahnen]],0,0),"") -> 0.51041667 | X26: KSV Pockau-Lengefeld | Y26: Feldstraße 44, 09514 Pockau-Lengefeld | Z26: 9514 | AA26: =IF(Orte[[#This Row],[Anschrift]]="",Orte[[#This Row],[Kurzform]],RIGHT(Orte[[#This Row],[Anschrift]],LEN(Orte[[#This Row],[Anschrift]])-FIND("#",SUBSTITUTE(Orte[[#This Row],[Anschrift]]," ","#",LEN(Orte[[#This Row],[Anschrift]])-LEN(SUBSTITUTE(Orte[[#This Row],[Anschrift]]," ",)))))) -> Pockau-Lengefeld | AB26: Pockau | AC26: 4
